Workbook

Sheet Note
A1: Processes are more specific and represent the flow of activities within a particular domain.
A2: Technology focuses on the tools and resources used to accomplish tasks
A5: Mapping reference
A6: Datasheet | B6: Link | C6: check | D6: note
A7: Reptool | B7: sharepoint | C7: V | D7: discuss on Thur.
A8: ecoinvent 3.1.9 | B8: sharepoint | C8: V | D8: use activity browser to check the treatment flows
A9: Mining waste_Second version Data Template_vGeoZS_conn_MIN4EU | B9: offline | C9: V | D9: sharepoint_termporary version
A10: CDW flowchart | B10: miro | C10: V
A11: ELV flowchart | B11: miro | C11: V
A12: BATT flowchart | B12: miro | C12: V | D12: pyrometallurgical processes (BATT smelting, pyrolysis, roasting)
A13: WEEE flowchart | B13: miro | C13: V
A14: SLASH flowchart | B14: miro | C14: V | D14: In thr mechRP, shredding is separated from comminution.
A15: MINW flowchart | B15: miro | C15: V | D15: check where should put "bottom ash treatment"
A17: Tales model logistic
B37: intro
B38: generic or specific (make example, crushing

Sheet Intro
A2: Project name | B2: FutuRaM
A3: File name | B3: FutuRaM_process_codelists_WP3
A4: Version history | B4: 1th | C4: TUB, 17.07.2023
A6: Responsible | B6: Rebecca (Han-jung) Hu | C6: hu@tu-berlin.de
A8: Introdution
A9: Purpose | B9: The process/technology code ID in this codelist is used for the "transfer coefficients template".
A10: Sheet-Diagram | B10: An overview of all the processes.
A11: Sheet-Level 1 | B11: General main processes for the waste streams, including production, distribution and usage, collection, preparation for reuse, recovery processes and disposal.
A12: Sheet-Level 2 | B12: The processes are under the main processes (level 1).
A13: Sheet-Level 3 | B13: The processes are under the sub processes (level 2), more refer to specific technologies.
A15: Instructions on usage
A16: Sheets marked orange | B16: The codelists/code should only be changed/extended in consultation with the responsible person.
A17: Sheets marked green | B17: Everyone can add new codes to the list (level 3), changes in the existing codes should only be done in consultation with the responsible person. Naming convention: In the general situation, please pick "three characters" from the "process name" with uppercase letters as the code, then add "_" and the "level" at the end. e.g. smelting->SME_L2 Note! No blanks should be used within the codes.

Sheet Diagram
A1: level1 (main) processes | B1: code | C1: description | D1: level 2 processes | E1: code | F1: description | G1: level 3 processes (technology) | H1: code | I1: description
A2: =Level1!A2 -> production | B2: =VLOOKUP(A2,Level1_process_list[],2,0) -> PRO_L1 | C2: =VLOOKUP(A2,Level1_process_list[],3,0) -> The processes include smelting, refining, fabrication and manufacturing. | D2: =Level2!A2 -> smelting | E2: =VLOOKUP(D2,Level2_process_list[],2,0) -> SME_L2 | F2: =VLOOKUP(D2,Level2_process_list[],3,0) -> The valuable materials are subjected to high temperatures to melt, separating them from the other components then be collected and further processed. | G2: =Level3!A2 -> aluminium smelting | H2: =VLOOKUP(G2,Level3_process_list[],2,0) -> AIS_L3 | I2: =VLOOKUP(G2,Level3_process_list[],3,0) -> The process of recycling aluminum scrap and waste materials to extract aluminum metal.
G3: =Level3!A3 -> iron smelting | H3: =VLOOKUP(G3,Level3_process_list[],2,0) -> FeS_L3 | I3: =VLOOKUP(G3,Level3_process_list[],3,0) -> The process of recycling iron scrap and waste materials to extract iron metal.
G4: =Level3!A4 -> integrated copper smelting | H4: =VLOOKUP(G4,Level3_process_list[],2,0) -> INTCuS_L3 | I4: =VLOOKUP(G4,Level3_process_list[],3,0) -> The process involves the extraction of copper from sulfide ores in a single facility
G5: =Level3!A5 -> standard copper smelting | H5: =VLOOKUP(G5,Level3_process_list[],2,0) -> STACuS_L3 | I5: =VLOOKUP(G5,Level3_process_list[],3,0) -> The process focuses on recycling and processing copper-containing materials without the need for mining and beneficiation.
G6: =Level3_process_list[[#This Row],[level 3 processes (technology)]] -> lead smelting | H6: =VLOOKUP(G6,Level3_process_list[],2,0) -> PbS_L3 | I6: =VLOOKUP(G6,Level3_process_list[],3,0) -> The process of recycling lead scrap and waste materials to extract lead metal.
D7: =Level2!A3 -> refining | E7: =VLOOKUP(D7,Level2_process_list[],2,0) -> REF_L2 | F7: =VLOOKUP(D7,Level2_process_list[],3,0) -> The process involves further purification, removal of impurities, or alloying to achieve the desired properties.
D8: =Level2!A4 -> fabrication and manufacturing | E8: =VLOOKUP(D8,Level2_process_list[],2,0) -> FAM_L2 | F8: =VLOOKUP(D8,Level2_process_list[],3,0) -> Fabrication involves assembling parts or materials to create a product. Manufacturing includes fabrication, assembly, and other processes.
D9: =Level2!A5 -> construction | E9: =VLOOKUP(D9,Level2_process_list[],2,0) -> CON_L2 | F9: =VLOOKUP(D9,Level2_process_list[],3,0) -> The activities and steps involved in building structures or infrastructure.
A10: =Level1!A3 -> distribution and usage | B10: =VLOOKUP(A10,Level1_process_list[],2,0) -> DAU_L1 | C10: =VLOOKUP(A10,Level1_process_list[],3,0) -> The processes include the products put on the market and their usage. | D10: =Level2!A6 -> usage | E10: =VLOOKUP(D10,Level2_process_list[],2,0) -> USE_L2 | F10: =VLOOKUP(D10,Level2_process_list[],3,0) -> The usage activities include reuse and repair.
A11: =Level1!A4 -> collection | B11: =VLOOKUP(A11,Level1_process_list[],2,0) -> COL_L1 | C11: =VLOOKUP(A11,Level1_process_list[],3,0) -> The processes gather the generated waste. | D11: =Level2!A7 -> dedicated collection | E11: =VLOOKUP(D11,Level2_process_list[],2,0) -> DED_L2 | F11: =VLOOKUP(D11,Level2_process_list[],3,0) -> The specialized collection of specific waste streams or materials that require separate handling due to their unique characteristics or potential for recycling.
D12: =Level2!A8 -> complementary collection | E12: =VLOOKUP(D12,Level2_process_list[],2,0) -> CPT_L2 | F12: =VLOOKUP(D12,Level2_process_list[],3,0) -> It is an additional collection process that complements the existing waste management system to address specific waste streams or materials that require separate handling or treatment (e.g. hazardous materials, electronic waste, bulky items, construction and demolition waste).
D13: =Level2!A9 -> CDW collection separate | E13: =VLOOKUP(D13,Level2_process_list[],2,0) -> CCS_L2 | F13: =VLOOKUP(D13,Level2_process_list[],3,0) -> After selective deconstruction and demolition waste, the collection is separated.
D14: =Level2!A10 -> CDW collection mix | E14: =VLOOKUP(D14,Level2_process_list[],2,0) -> CCM_L2 | F14: =VLOOKUP(D14,Level2_process_list[],3,0) -> After the classical demolition (e.g. blasting, smashing), certain components might be removed beforehand, and the collection is mixed.
A15: =Level1!A5 -> preparation for reuse | B15: =VLOOKUP(A15,Level1_process_list[],2,0) -> PFR_L1 | C15: =VLOOKUP(A15,Level1_process_list[],3,0) -> The process checks whether the waste is reusable or not, then checks part of the waste is functional or not, and distributes it to the reuse stage. | D15: =Level2!A11 -> categorizing | E15: =VLOOKUP(D15,Level2_process_list[],2,0) -> CAT_L2 | F15: =VLOOKUP(D15,Level2_process_list[],3,0) -> The process to classify whether the waste item is reusable or not. | H15: =VLOOKUP(G15,Level3_process_list[],2,0) -> #N/A | I15: =VLOOKUP(G15,Level3_process_list[],3,0) -> #N/A
D16: inspection | H16: =VLOOKUP(G16,Level3_process_list[],2,0) -> #N/A | I16: =VLOOKUP(G16,Level3_process_list[],3,0) -> #N/A
D17: =Level2!A13 -> disassembling | E17: =VLOOKUP(D17,Level2_process_list[],2,0) -> DIS_L2 | F17: =VLOOKUP(D17,Level2_process_list[],3,0) -> The process to remove functional units from the waste item.
D18: =Level2!A14 -> test and repair | E18: =VLOOKUP(D18,Level2_process_list[],2,0) -> TAR_L2 | F18: =VLOOKUP(D18,Level2_process_list[],3,0) -> The process to test and repair the functional units.
A19: =Level1!A6 -> mechanical recovery processes | B19: =VLOOKUP(A19,Level1_process_list[],2,0) -> MEC_L1 | C19: =VLOOKUP(A19,Level1_process_list[],3,0) -> The processes rely on physical comminution, separation, agglomeration, and mixing for recovery of the waste. | D19: =Level2!A15 -> comminution | E19: =VLOOKUP(D19,Level2_process_list[],2,0) -> COM_L2 | F19: =VLOOKUP(D19,Level2_process_list[],3,0) -> Refers to the process of reducing the size of waste materials through shredding, grinding, or crushing. | G19: =Level3!A7 -> shredding | H19: =VLOOKUP(G19,Level3_process_list[],2,0) -> SHR_L3 | I19: =VLOOKUP(G19,Level3_process_list[],3,0) -> Breaking waste materials into smaller strips.
G20: =Level3!A8 -> grinding | H20: =VLOOKUP(G20,Level3_process_list[],2,0) -> GRI_L3 | I20: =VLOOKUP(G20,Level3_process_list[],3,0) -> Reducing waste into fine particles or powders.
G21: =Level3!A9 -> cutting | H21: =VLOOKUP(G21,Level3_process_list[],2,0) -> CUT_L3 | I21: =VLOOKUP(G21,Level3_process_list[],3,0) -> Separating waste along a specific path.
G22: =Level3!A10 -> crushing | H22: =VLOOKUP(G22,Level3_process_list[],2,0) -> CRU_L3 | I22: =VLOOKUP(G22,Level3_process_list[],3,0) -> Compressing waste to reduce size or alter its physical structure.
D23: =Level2!A16 -> separation | E23: =VLOOKUP(D23,Level2_process_list[],2,0) -> SEP_L2 | F23: =VLOOKUP(D23,Level2_process_list[],3,0) -> Separation based on the waste properties such as size, shape, density, and magnetic properties, including such as mechanical sorting, screening, magnetic separation. | G23: =Level3!A11 -> dismantling | H23: =VLOOKUP(G23,Level3_process_list[],2,0) -> DIS_L3 | I23: =VLOOKUP(G23,Level3_process_list[],3,0) -> The systematic disassembly of electronic devices or equipment into their individual components or parts.
G24: =Level3!A12 -> depollution
G25: =Level3!A13 -> coating removal
G26: =Level3!A14 -> emptying
G27: =Level3!A15 -> sieving | H27: =VLOOKUP(G27,Level3_process_list[],2,0) -> SIE_L3 | I27: =VLOOKUP(G27,Level3_process_list[],3,0) -> The process of separating solid waste materials by passing them through a sieve or mesh with different-sized openings. AKA screening.
G28: =Level3!A16 -> manual sorting | H28: =VLOOKUP(G28,Level3_process_list[],2,0) -> MAS_L3 | I28: =VLOOKUP(G28,Level3_process_list[],3,0) -> The process involves the visual inspection and hand-picking of waste materials by workers. Examine and separate the waste based on specific criteria such as material type, color, shape, or composition.
G29: =Level3!A17 -> flotation | H29: =VLOOKUP(G29,Level3_process_list[],2,0) -> FLO_L3 | I29: =VLOOKUP(G29,Level3_process_list[],3,0) -> A process based on density property to separate materials with low-density differences, such as plastics from mixed waste streams.
G30: =Level3!A18 -> sedimentation | H30: =VLOOKUP(G30,Level3_process_list[],2,0) -> SED_L3 | I30: =VLOOKUP(G30,Level3_process_list[],3,0) -> A process based on the principle of gravity settling, where waste particles settle out of a liquid or slurry due to their different densities.
G31: =Level3!A19 -> air classification | H31: =VLOOKUP(G31,Level3_process_list[],2,0) -> AIC_L3 | I31: =VLOOKUP(G31,Level3_process_list[],3,0) -> A process used to separate waste materials based on their particle size and density using air currents. Air classification is effective in separating materials with varying particle sizes.
G32: =Level3!A20 -> magnetic separation | H32: =VLOOKUP(G32,Level3_process_list[],2,0) -> MAGS_L3 | I32: =VLOOKUP(G32,Level3_process_list[],3,0) -> Using magnets to separate ferrous (magnetic) materials such as iron and steel from non-ferrous materials.
G33: =Level3!A21 -> eddy current separation | H33: =VLOOKUP(G33,Level3_process_list[],2,0) -> ECS_L3 | I33: =VLOOKUP(G33,Level3_process_list[],3,0) -> Focusing specifically on separating non-ferrous metals such as aluminum and copper using the principles of electromagnetic induction.
G34: =Level3!A23 -> Near InfraRed spectroscopy | H34: =VLOOKUP(G34,Level3_process_list[],2,0) -> NIRS_L3 | I34: =VLOOKUP(G34,Level3_process_list[],3,0) -> Analyzing the chemical composition of materials based on their interaction with near-infrared light.
G35: =Level3!A24 -> Laser Induced Breakdown Spectroscopy | H35: =VLOOKUP(G35,Level3_process_list[],2,0) -> LIBS_L3 | I35: =VLOOKUP(G35,Level3_process_list[],3,0) -> Determining the elemental composition of a sample by analyzing the light emitted during the laser-induced plasma formation.
G36: =Level3!A25 -> X-ray fluorescence | H36: =VLOOKUP(G36,Level3_process_list[],2,0) -> XRF_L3 | I36: =VLOOKUP(G36,Level3_process_list[],3,0) -> Determining the elemental composition of a material by measuring characteristic X-ray emissions.
D37: =Level2!A17 -> agglomeration | E37: =VLOOKUP(D37,Level2_process_list[],2,0) -> AGG_L2 | F37: =VLOOKUP(D37,Level2_process_list[],3,0) -> Also known as pelletization or briquetting, involves compacting waste materials into larger units for improved handling and utilization.
D38: =Level2!A18 -> mixing | E38: =VLOOKUP(D38,Level2_process_list[],2,0) -> MIX_L2 | F38: =VLOOKUP(D38,Level2_process_list[],3,0) -> The mechanical mixing of powder containing two or multiple different components, that is needed to be mixed, in a high-speed mixer or in a ball mill.
A39: =Level1!A7 -> biological recovery processes | B39: =VLOOKUP(A39,Level1_process_list[],2,0) -> BIO_L1 | C39: =VLOOKUP(A39,Level1_process_list[],3,0) -> The processes use natural biological mechanisms for example aerobic or anaerobic treatments to break down or transform waste materials. | D39: =Level2!A19 -> aerobic | E39: =VLOOKUP(D39,Level2_process_list[],2,0) -> AER_L2 | F39: =VLOOKUP(D39,Level2_process_list[],3,0) -> The use of microorganisms that require oxygen to decompose and transform organic waste materials into simpler and more stable compounds.
D40: =Level2!A20 -> anaerobic | E40: =VLOOKUP(D40,Level2_process_list[],2,0) -> ANAER_L2 | F40: =VLOOKUP(D40,Level2_process_list[],3,0) -> The use of microorganisms that can decompose organic waste materials in the absence of oxygen.
...

Sheet Level1
A1: level 1 processes | B1: code 1 | C1: description
A2: production | B2: PRO_L1 | C2: The processes include smelting, refining, fabrication and manufacturing.
A3: distribution and usage | B3: DAU_L1 | C3: The processes include the products put on the market and their usage.
A4: collection | B4: COL_L1 | C4: The processes gather the generated waste.
A5: preparation for reuse | B5: PFR_L1 | C5: The process checks whether the waste is reusable or not, then checks part of the waste is functional or not, and distributes it to the reuse stage.
A6: mechanical recovery processes | B6: MEC_L1 | C6: The processes rely on physical comminution, separation, agglomeration, and mixing for recovery of the waste.
A7: biological recovery processes | B7: BIO_L1 | C7: The processes use natural biological mechanisms for example aerobic or anaerobic treatments to break down or transform waste materials.
A8: thermal recovery processes | B8: THE_L1 | C8: The processes involve the application of heat to treat or recover waste materials, for example incineration, pyrolysis and gasification.
A9: chemical recovery processes | B9: CHE_L1 | C9: The processes use chemical reactions to transform waste materials or extract valuable components, for example, leaching, extraction, and distillation.
A10: disposal processes | B10: DIS_L1 | C10: The process is the final step when waste materials cannot be effectively recovered or treated.

Sheet Level2
A1: level 2 processes | B1: code 2 | C1: description | D1: level1 processes | E1: code 1 | F1: note
A2: smelting | B2: SME_L2 | C2: The valuable materials are subjected to high temperatures to melt, separating them from the other components then be collected and further processed. | D2: production | E2: =VLOOKUP(D2,Level1_process_list[],2,0) -> PRO_L1 | F2: The inputs are SRM mostly from CDW, WEEE and ELV mechanical recovery processes.
A3: refining | B3: REF_L2 | C3: The process involves further purification, removal of impurities, or alloying to achieve the desired properties. | D3: production | E3: =VLOOKUP(D3,Level1_process_list[],2,0) -> PRO_L1
A4: fabrication and manufacturing | B4: FAM_L2 | C4: Fabrication involves assembling parts or materials to create a product. Manufacturing includes fabrication, assembly, and other processes. | D4: production | E4: =VLOOKUP(D4,Level1_process_list[],2,0) -> PRO_L1
A5: construction | B5: CON_L2 | C5: The activities and steps involved in building structures or infrastructure. | D5: production | E5: =VLOOKUP(D5,Level1_process_list[],2,0) -> PRO_L1
A6: usage | B6: USE_L2 | C6: The usage activities include reuse and repair. | D6: distribution and usage | E6: =VLOOKUP(D6,Level1_process_list[],2,0) -> DAU_L1
A7: dedicated collection | B7: DED_L2 | C7: The specialized collection of specific waste streams or materials that require separate handling due to their unique characteristics or potential for recycling. | D7: collection | E7: =VLOOKUP(D7,Level1_process_list[],2,0) -> COL_L1 | F7: BATT, WEEE flows
A8: complementary collection | B8: CPT_L2 | C8: It is an additional collection process that complements the existing waste management system to address specific waste streams or materials that require separate handling or treatment (e.g. hazardous materials, electronic waste, bulky items, construction and demolition waste). | D8: collection | E8: =VLOOKUP(D8,Level1_process_list[],2,0) -> COL_L1 | F8: BATT, WEEE flows
A9: CDW collection separate | B9: CCS_L2 | C9: After selective deconstruction and demolition waste, the collection is separated. | D9: collection | E9: =VLOOKUP(D9,Level1_process_list[],2,0) -> COL_L1
A10: CDW collection mix | B10: CCM_L2 | C10: After the classical demolition (e.g. blasting, smashing), certain components might be removed beforehand, and the collection is mixed. | D10: collection | E10: =VLOOKUP(D10,Level1_process_list[],2,0) -> COL_L1
A11: categorizing | B11: CAT_L2 | C11: The process to classify whether the waste item is reusable or not. | D11: preparation for reuse | E11: =VLOOKUP(D11,Level1_process_list[],2,0) -> PFR_L1
A12: inspection | B12: INS_L2 | C12: The process to examine the units of the waste item is functional or not. | D12: preparation for reuse | E12: =VLOOKUP(D12,Level1_process_list[],2,0) -> PFR_L1
A13: disassembling | B13: DIS_L2 | C13: The process to remove functional units from the waste item. | D13: preparation for reuse | E13: =VLOOKUP(D13,Level1_process_list[],2,0) -> PFR_L1
A14: test and repair | B14: TAR_L2 | C14: The process to test and repair the functional units. | D14: preparation for reuse | E14: =VLOOKUP(D14,Level1_process_list[],2,0) -> PFR_L1
A15: comminution | B15: COM_L2 | C15: Refers to the process of reducing the size of waste materials through shredding, grinding, or crushing. | D15: mechanical recovery processes | E15: =VLOOKUP(D15,Level1_process_list[],2,0) -> MEC_L1
A16: separation | B16: SEP_L2 | C16: Separation based on the waste properties such as size, shape, density, and magnetic properties, including such as mechanical sorting, screening, magnetic separation. | D16: mechanical recovery processes | E16: =VLOOKUP(D16,Level1_process_list[],2,0) -> MEC_L1
A17: agglomeration | B17: AGG_L2 | C17: Also known as pelletization or briquetting, involves compacting waste materials into larger units for improved handling and utilization. | D17: mechanical recovery processes | E17: =VLOOKUP(D17,Level1_process_list[],2,0) -> MEC_L1
A18: mixing | B18: MIX_L2 | C18: The mechanical mixing of powder containing two or multiple different components, that is needed to be mixed, in a high-speed mixer or in a ball mill. | D18: mechanical recovery processes | E18: =VLOOKUP(D18,Level1_process_list[],2,0) -> MEC_L1
A19: aerobic | B19: AER_L2 | C19: The use of microorganisms that require oxygen to decompose and transform organic waste materials into simpler and more stable compounds. | D19: biological recovery processes | E19: =VLOOKUP(D19,Level1_process_list[],2,0) -> BIO_L1
A20: anaerobic | B20: ANAER_L2 | C20: The use of microorganisms that can decompose organic waste materials in the absence of oxygen. | D20: biological recovery processes | E20: =VLOOKUP(D20,Level1_process_list[],2,0) -> BIO_L1
... A25: pyrolysis | B25: PYR_L2 | C25: Converting organic materials, such as biomass or waste, into a mixture of solid, liquid, and gas products in the absence of oxygen. | D25: thermal recovery processes | E25: =VLOOKUP(D25,Level1_process_list[],2,0) -> THE_L1
A26: BATTsmelting | B26: BATTS_L2 | C26: The high-temperature treatment of the batteries to extract valuable metals, such as lead and other metallic components. | D26: thermal recovery processes | E26: =VLOOKUP(D26,Level1_process_list[],2,0) -> THE_L1 | F26: BATT
A27: roasting | B27: ROA_L2 | C27: Heating the material to a specific temperature range, which causes various chemical reactions, such as oxidation, volatilization, or phase transformations, leading to the desired recovery of valuable components. | D27: thermal recovery processes | E27: =VLOOKUP(D27,Level1_process_list[],2,0) -> THE_L1 | F27: BATT
A28: vaporization | B28: VAP_L2 | C28: The stage to pure the black mass (the mixture of electrode materials, including carbon black, binders, and active materials) by the conversion of a substance from a liquid or solid state to a gaseous state. | D28: thermal recovery processes | E28: =VLOOKUP(D28,Level1_process_list[],2,0) -> THE_L1 | F28: BATT
A29: vacuum furnace | B29: VAF_L2 | C29: A process for controlled heating processes under low-pressure or vacuum conditions. It is commonly used for various heat treatment applications such as annealing, brazing, sintering, and tempering of metals. | D29: thermal recovery processes | E29: =VLOOKUP(D29,Level1_process_list[],2,0) -> THE_L1 | F29: BATT
A30: leaching | B30: LEA_L2 | C30: The use of a solvent to dissolve valuable components from the waste material. | D30: chemical recovery processes | E30: =VLOOKUP(D30,Level1_process_list[],2,0) -> CHE_L1
A31: extraction | B31: EXT_L2 | C31: It is similar to leaching, but the solvent selectively dissolves the desired compound, allowing it to be separated from the remaining waste or other unwanted compounds. | D31: chemical recovery processes | E31: =VLOOKUP(D31,Level1_process_list[],2,0) -> CHE_L1
A32: distillation | B32: DIST_L2 | C32: A process that involves the separation of different components in a mixture based on their boiling points. | D32: chemical recovery processes | E32: =VLOOKUP(D32,Level1_process_list[],2,0) -> CHE_L1
A33: precipitation | B33: PRE_L2 | C33: A process that involves the formation of solid particles in a solution. It is used in waste chemical recovery to selectively separate and recover specific compounds from a solution. | D33: chemical recovery processes | E33: =VLOOKUP(D33,Level1_process_list[],2,0) -> CHE_L1
A34: conditioning | B34: COD_L2 | C34: The preparation or treatment of the waste material to make it more suitable for subsequent processing steps. | D34: chemical recovery processes | E34: =VLOOKUP(D34,Level1_process_list[],2,0) -> CHE_L1
A35: electrolysis | B35: ELE_L2 | C35: A process uses an electric current to recover metals or transform compounds. | D35: chemical recovery processes | E35: =VLOOKUP(D35,Level1_process_list[],2,0) -> CHE_L1
A36: reduction | B36: RED_L2 | C36: The use of chemical agents or compounds to facilitate the reduction of metal oxides present in the ash. | D36: chemical recovery processes | E36: =VLOOKUP(D36,Level1_process_list[],2,0) -> CHE_L1 | F36: SLASH
A37: re-dissolution | B37: RDIS_L2 | C37: Treating the reduced ash with suitable chemicals or leaching agents to selectively dissolve the desired metals while minimizing the dissolution of unwanted components. | D37: chemical recovery processes | E37: =VLOOKUP(D37,Level1_process_list[],2,0) -> CHE_L1 | F37: SLASH
A38: cementation | B38: CEM_L2 | C38: A metal ion is reduced and deposited onto a solid metal surface, known as the cementing agent, through a redox reaction. Whereas in traditional precipitation processes, the solid phase is formed independently in the solution. | D38: chemical recovery processes | E38: =VLOOKUP(D38,Level1_process_list[],2,0) -> CHE_L1 | F38: SLASH
A39: chlorination | B39: CHL_L2 | C39: Treating the metal-rich solution with chlorine to form metal chlorides for subsequent separation and processing. | D39: chemical recovery processes | E39: =VLOOKUP(D39,Level1_process_list[],2,0) -> CHE_L1 | F39: SLASH
A40: landfilling | B40: LAN_L2 | C40: Burying waste in designated areas for disposal. | D40: disposal processes | E40: =VLOOKUP(D40,Level1_process_list[],2,0) -> DIS_L1
A41: neutralization for landfills | B41: NFL_L2 | C41: Treating acidic leachate (liquid produced from decomposing waste) to adjust its pH towards a neutral level. | D41: disposal processes | E41: =VLOOKUP(D41,Level1_process_list[],2,0) -> DIS_L1
A42: incineration for disposal | B42: INCDIS_L2 | C42: The controlled burning of waste to reduce volume and produce ash, gas, and heat. | D42: disposal processes | E42: =VLOOKUP(D42,Level1_process_list[],2,0) -> DIS_L1
A43: interim storage | B43: ITS_L2 | C43: The temporary containment or storage of waste materials before they are further processed or disposed of. | D43: disposal processes | E43: =VLOOKUP(D43,Level1_process_list[],2,0) -> DIS_L1
A44: testing added row kirsten | E44: =VLOOKUP(D44,Level1_process_list[],2,0) -> #N/A
...

Sheet Level3
A1: level 3 processes (technology) | B1: code 3 | C1: description | D1: level 2 processes | E1: code 2 | F1: level1 processes | G1: code 1 | H1: note
A2: aluminium smelting | B2: AIS_L3 | C2: The process of recycling aluminum scrap and waste materials to extract aluminum metal. | D2: smelting | E2: =VLOOKUP(D2,Level2_process_list[],2,0) -> SME_L2 | F2: =VLOOKUP(D2,Level2_process_list[],4,0) -> production | G2: =VLOOKUP(D2,Level2_process_list[],5,0) -> PRO_L1
A3: iron smelting | B3: FeS_L3 | C3: The process of recycling iron scrap and waste materials to extract iron metal. | D3: smelting | E3: =VLOOKUP(D3,Level2_process_list[],2,0) -> SME_L2 | F3: =VLOOKUP(D3,Level2_process_list[],4,0) -> production | G3: =VLOOKUP(D3,Level2_process_list[],5,0) -> PRO_L1
A4: integrated copper smelting | B4: INTCuS_L3 | C4: The process involves the extraction of copper from sulfide ores in a single facility | D4: smelting | E4: =VLOOKUP(D4,Level2_process_list[],2,0) -> SME_L2 | F4: =VLOOKUP(D4,Level2_process_list[],4,0) -> production | G4: =VLOOKUP(D4,Level2_process_list[],5,0) -> PRO_L1
A5: standard copper smelting | B5: STACuS_L3 | C5: The process focuses on recycling and processing copper-containing materials without the need for mining and beneficiation. | D5: smelting | E5: =VLOOKUP(D5,Level2_process_list[],2,0) -> SME_L2 | F5: =VLOOKUP(D5,Level2_process_list[],4,0) -> production | G5: =VLOOKUP(D5,Level2_process_list[],5,0) -> PRO_L1
A6: lead smelting | B6: PbS_L3 | C6: The process of recycling lead scrap and waste materials to extract lead metal. | D6: smelting | E6: =VLOOKUP(D6,Level2_process_list[],2,0) -> SME_L2 | F6: =VLOOKUP(D6,Level2_process_list[],4,0) -> production | G6: =VLOOKUP(D6,Level2_process_list[],5,0) -> PRO_L1
A7: shredding | B7: SHR_L3 | C7: Breaking waste materials into smaller strips. | D7: comminution | E7: =VLOOKUP(D7,Level2_process_list[],2,0) -> COM_L2 | F7: =VLOOKUP(D7,Level2_process_list[],4,0) -> mechanical recovery processes | G7: =VLOOKUP(D7,Level2_process_list[],5,0) -> MEC_L1
A8: grinding | B8: GRI_L3 | C8: Reducing waste into fine particles or powders. | D8: comminution | E8: =VLOOKUP(D8,Level2_process_list[],2,0) -> COM_L2 | F8: =VLOOKUP(D8,Level2_process_list[],4,0) -> mechanical recovery processes | G8: =VLOOKUP(D8,Level2_process_list[],5,0) -> MEC_L1
A9: cutting | B9: CUT_L3 | C9: Separating waste along a specific path. | D9: comminution | E9: =VLOOKUP(D9,Level2_process_list[],2,0) -> COM_L2 | F9: =VLOOKUP(D9,Level2_process_list[],4,0) -> mechanical recovery processes | G9: =VLOOKUP(D9,Level2_process_list[],5,0) -> MEC_L1
A10: crushing | B10: CRU_L3 | C10: Compressing waste to reduce size or alter its physical structure. | D10: comminution | E10: =VLOOKUP(D10,Level2_process_list[],2,0) -> COM_L2 | F10: =VLOOKUP(D10,Level2_process_list[],4,0) -> mechanical recovery processes | G10: =VLOOKUP(D10,Level2_process_list[],5,0) -> MEC_L1
A11: dismantling | B11: DIS_L3 | C11: The systematic disassembly of electronic devices or equipment into their individual components or parts. | D11: separation | E11: =VLOOKUP(D11,Level2_process_list[],2,0) -> SEP_L2 | F11: =VLOOKUP(D11,Level2_process_list[],4,0) -> mechanical recovery processes | G11: =VLOOKUP(D11,Level2_process_list[],5,0) -> MEC_L1 | H11: WEEE
A12: depollution | B12: DEP_L3 | C12: The process of removing hazardous substances or pollutants from WEEE before further processing or disposal. | D12: separation | E12: =VLOOKUP(D12,Level2_process_list[],2,0) -> SEP_L2 | F12: =VLOOKUP(D12,Level2_process_list[],4,0) -> mechanical recovery processes | G12: =VLOOKUP(D12,Level2_process_list[],5,0) -> MEC_L1 | H12: WEEE, BATT
A13: coating removal | B13: COR_L3 | C13: The process of stripping or removing protective coatings from electronic components or surfaces. | D13: separation | E13: =VLOOKUP(D13,Level2_process_list[],2,0) -> SEP_L2 | F13: =VLOOKUP(D13,Level2_process_list[],4,0) -> mechanical recovery processes | G13: =VLOOKUP(D13,Level2_process_list[],5,0) -> MEC_L1 | H13: WEEE
A14: emptying | B14: EMP_L3 | C14: The removal of any remaining contents or substances from the battery before it undergoes further processing. | D14: separation | E14: =VLOOKUP(D14,Level2_process_list[],2,0) -> SEP_L2 | F14: =VLOOKUP(D14,Level2_process_list[],4,0) -> mechanical recovery processes | G14: =VLOOKUP(D14,Level2_process_list[],5,0) -> MEC_L1 | H14: BATT
A15: sieving | B15: SIE_L3 | C15: The process of separating solid waste materials by passing them through a sieve or mesh with different-sized openings. AKA screening. | D15: separation | E15: =VLOOKUP(D15,Level2_process_list[],2,0) -> SEP_L2 | F15: =VLOOKUP(D15,Level2_process_list[],4,0) -> mechanical recovery processes | G15: =VLOOKUP(D15,Level2_process_list[],5,0) -> MEC_L1
A16: manual sorting | B16: MAS_L3 | C16: The process involves the visual inspection and hand-picking of waste materials by workers. Examine and separate the waste based on specific criteria such as material type, color, shape, or composition. | D16: separation | E16: =VLOOKUP(D16,Level2_process_list[],2,0) -> SEP_L2 | F16: =VLOOKUP(D16,Level2_process_list[],4,0) -> mechanical recovery processes | G16: =VLOOKUP(D16,Level2_process_list[],5,0) -> MEC_L1
A17: flotation | B17: FLO_L3 | C17: A process based on density property to separate materials with low-density differences, such as plastics from mixed waste streams. | D17: separation | E17: =VLOOKUP(D17,Level2_process_list[],2,0) -> SEP_L2 | F17: =VLOOKUP(D17,Level2_process_list[],4,0) -> mechanical recovery processes | G17: =VLOOKUP(D17,Level2_process_list[],5,0) -> MEC_L1
A18: sedimentation | B18: SED_L3 | C18: A process based on the principle of gravity settling, where waste particles settle out of a liquid or slurry due to their different densities. | D18: separation | E18: =VLOOKUP(D18,Level2_process_list[],2,0) -> SEP_L2 | F18: =VLOOKUP(D18,Level2_process_list[],4,0) -> mechanical recovery processes | G18: =VLOOKUP(D18,Level2_process_list[],5,0) -> MEC_L1
A19: air classification | B19: AIC_L3 | C19: A process used to separate waste materials based on their particle size and density using air currents. Air classification is effective in separating materials with varying particle sizes. | D19: separation | E19: =VLOOKUP(D19,Level2_process_list[],2,0) -> SEP_L2 | F19: =VLOOKUP(D19,Level2_process_list[],4,0) -> mechanical recovery processes | G19: =VLOOKUP(D19,Level2_process_list[],5,0) -> MEC_L1
A20: magnetic separation | B20: MAGS_L3 | C20: Using magnets to separate ferrous (magnetic) materials such as iron and steel from non-ferrous materials. | D20: separation | E20: =VLOOKUP(D20,Level2_process_list[],2,0) -> SEP_L2 | F20: =VLOOKUP(D20,Level2_process_list[],4,0) -> mechanical recovery processes | G20: =VLOOKUP(D20,Level2_process_list[],5,0) -> MEC_L1
A21: eddy current separation | B21: ECS_L3 | C21: Focusing specifically on separating non-ferrous metals such as aluminum and copper using the principles of electromagnetic induction. | D21: separation | E21: =VLOOKUP(D21,Level2_process_list[],2,0) -> SEP_L2 | F21: =VLOOKUP(D21,Level2_process_list[],4,0) -> mechanical recovery processes | G21: =VLOOKUP(D21,Level2_process_list[],5,0) -> MEC_L1
A22: electrostatic separation | B22: ESS_L3 | C22: Using the electrical conductivity or electrostatic properties to separate a wide range of materials. It is applied to various materials such as plastics, metals, minerals, and electronic waste. | D22: separation | E22: =VLOOKUP(D22,Level2_process_list[],2,0) -> SEP_L2 | F22: =VLOOKUP(D22,Level2_process_list[],4,0) -> mechanical recovery processes | G22: =VLOOKUP(D22,Level2_process_list[],5,0) -> MEC_L1
A23: Near InfraRed spectroscopy | B23: NIRS_L3 | C23: Analyzing the chemical composition of materials based on their interaction with near-infrared light. | D23: separation | E23: =VLOOKUP(D23,Level2_process_list[],2,0) -> SEP_L2 | F23: =VLOOKUP(D23,Level2_process_list[],4,0) -> mechanical recovery processes | G23: =VLOOKUP(D23,Level2_process_list[],5,0) -> MEC_L1
A24: Laser Induced Breakdown Spectroscopy | B24: LIBS_L3 | C24: Determining the elemental composition of a sample by analyzing the light emitted during the laser-induced plasma formation. | D24: separation | E24: =VLOOKUP(D24,Level2_process_list[],2,0) -> SEP_L2 | F24: =VLOOKUP(D24,Level2_process_list[],4,0) -> mechanical recovery processes | G24: =VLOOKUP(D24,Level2_process_list[],5,0) -> MEC_L1
A25: X-ray fluorescence | B25: XRF_L3 | C25: Determining the elemental composition of a material by measuring characteristic X-ray emissions. | D25: separation | E25: =VLOOKUP(D25,Level2_process_list[],2,0) -> SEP_L2 | F25: =VLOOKUP(D25,Level2_process_list[],4,0) -> mechanical recovery processes | G25: =VLOOKUP(D25,Level2_process_list[],5,0) -> MEC_L1
A26: Add process or technology here | E26: =VLOOKUP(D26,Level2_process_list[],2,0) -> #N/A | F26: =VLOOKUP(D26,Level2_process_list[],4,0) -> #N/A | G26: =VLOOKUP(D26,Level2_process_list[],5,0) -> #N/A
